CUDA is available: True

Using 5 GPUs for model parallelization.
Traceback (most recent call last):
  File "/home/usuaris/imatge/joan.manel.cardenas/age_predictions/input_data.py", line 124, in <module>
    for inputs, age_dist, age_real, subject_ids in train_loader:
  File "/home/usuaris/imatge/joan.manel.cardenas/.local/lib/python3.10/site-packages/torch/utils/data/dataloader.py", line 631, in __next__
    data = self._next_data()
  File "/home/usuaris/imatge/joan.manel.cardenas/.local/lib/python3.10/site-packages/torch/utils/data/dataloader.py", line 1346, in _next_data
    return self._process_data(data)
  File "/home/usuaris/imatge/joan.manel.cardenas/.local/lib/python3.10/site-packages/torch/utils/data/dataloader.py", line 1372, in _process_data
    data.reraise()
  File "/home/usuaris/imatge/joan.manel.cardenas/.local/lib/python3.10/site-packages/torch/_utils.py", line 722, in reraise
    raise exception
ValueError: Caught ValueError in DataLoader worker process 0.
Original Traceback (most recent call last):
  File "/home/usuaris/imatge/joan.manel.cardenas/.local/lib/python3.10/site-packages/torch/utils/data/_utils/worker.py", line 308, in _worker_loop
    data = fetcher.fetch(index)
  File "/home/usuaris/imatge/joan.manel.cardenas/.local/lib/python3.10/site-packages/torch/utils/data/_utils/fetch.py", line 51, in fetch
    data = [self.dataset[idx] for idx in possibly_batched_index]
  File "/home/usuaris/imatge/joan.manel.cardenas/.local/lib/python3.10/site-packages/torch/utils/data/_utils/fetch.py", line 51, in <listcomp>
    data = [self.dataset[idx] for idx in possibly_batched_index]
  File "/home/usuaris/imatge/joan.manel.cardenas/age_predictions/model/mri_dataset.py", line 35, in __getitem__
    mri_data_tensor, age_dist_tensor, age_tensor, subject_id = self.transform((mri_data_tensor, age_dist_tensor, age_tensor, subject_id))
  File "/home/usuaris/imatge/joan.manel.cardenas/.local/lib/python3.10/site-packages/torchvision/transforms/transforms.py", line 95, in __call__
    img = t(img)
  File "/home/usuaris/imatge/joan.manel.cardenas/age_predictions/input_data.py", line 46, in __call__
    mri_data_tensor = np.roll(mri_data_tensor, shift, axis=(1, 2, 3))
  File "/home/usuaris/imatge/joan.manel.cardenas/.local/lib/python3.10/site-packages/numpy/core/numeric.py", line 1206, in roll
    a = asanyarray(a)
ValueError: setting an array element with a sequence. The requested array has an inhomogeneous shape after 1 dimensions. The detected shape was (4,) + inhomogeneous part.