
CUDA is available: True
Traceback (most recent call last):
  File "/home/usuaris/imatge/joan.manel.cardenas/age_predictions/input_data.py", line 117, in <module>
    model = model.to(device)
  File "/home/usuaris/imatge/joan.manel.cardenas/.local/lib/python3.10/site-packages/torch/nn/modules/module.py", line 1152, in to
    return self._apply(convert)
  File "/home/usuaris/imatge/joan.manel.cardenas/.local/lib/python3.10/site-packages/torch/nn/modules/module.py", line 802, in _apply
    module._apply(fn)
  File "/home/usuaris/imatge/joan.manel.cardenas/.local/lib/python3.10/site-packages/torch/nn/modules/module.py", line 802, in _apply
    module._apply(fn)
  File "/home/usuaris/imatge/joan.manel.cardenas/.local/lib/python3.10/site-packages/torch/nn/modules/module.py", line 802, in _apply
    module._apply(fn)
  File "/home/usuaris/imatge/joan.manel.cardenas/.local/lib/python3.10/site-packages/torch/nn/modules/module.py", line 825, in _apply
    param_applied = fn(param)
  File "/home/usuaris/imatge/joan.manel.cardenas/.local/lib/python3.10/site-packages/torch/nn/modules/module.py", line 1150, in convert
    return t.to(device, dtype if t.is_floating_point() or t.is_complex() else None, non_blocking)
RuntimeError: CUDA error: out of memory
CUDA kernel errors might be asynchronously reported at some other API call, so the stacktrace below might be incorrect.
For debugging consider passing CUDA_LAUNCH_BLOCKING=1.
Compile with `TORCH_USE_CUDA_DSA` to enable device-side assertions.